Traceback (most recent call last):
  File "/Users/facer/opt/anaconda3/lib/python3.8/site-packages/jupyter_cache/executors/utils.py", line 58, in single_nb_execution
    executenb(
  File "/Users/facer/opt/anaconda3/lib/python3.8/site-packages/nbclient/client.py", line 1112, in execute
    return NotebookClient(nb=nb, resources=resources, km=km, **kwargs).execute()
  File "/Users/facer/opt/anaconda3/lib/python3.8/site-packages/nbclient/util.py", line 74, in wrapped
    return just_run(coro(*args, **kwargs))
  File "/Users/facer/opt/anaconda3/lib/python3.8/site-packages/nbclient/util.py", line 53, in just_run
    return loop.run_until_complete(coro)
  File "/Users/facer/opt/anaconda3/lib/python3.8/asyncio/base_events.py", line 616, in run_until_complete
    return future.result()
  File "/Users/facer/opt/anaconda3/lib/python3.8/site-packages/nbclient/client.py", line 553, in async_execute
    await self.async_execute_cell(
  File "/Users/facer/opt/anaconda3/lib/python3.8/site-packages/nbclient/client.py", line 857, in async_execute_cell
    self._check_raise_for_error(cell, exec_reply)
  File "/Users/facer/opt/anaconda3/lib/python3.8/site-packages/nbclient/client.py", line 760, in _check_raise_for_error
    raise CellExecutionError.from_cell_and_msg(cell, exec_reply_content)
nbclient.exceptions.CellExecutionError: An error occurred while executing the following cell:
------------------
y = np.ones((3))
y + a # y.shape: (3,)==>(1,3)ï¼Œæ— æ³•ç»§ç»­å¹¿æ’­
------------------

[0;31m---------------------------------------------------------------------------[0m
[0;31mValueError[0m                                Traceback (most recent call last)
[0;32m<ipython-input-14-4f463af64f83>[0m in [0;36m<module>[0;34m[0m
[1;32m      1[0m [0my[0m [0;34m=[0m [0mnp[0m[0;34m.[0m[0mones[0m[0;34m([0m[0;34m([0m[0;36m3[0m[0;34m)[0m[0;34m)[0m[0;34m[0m[0;34m[0m[0m
[0;32m----> 2[0;31m [0my[0m [0;34m+[0m [0ma[0m [0;31m# y.shape: (3,)==>(1,3)ï¼Œæ— æ³•ç»§ç»­å¹¿æ’­[0m[0;34m[0m[0;34m[0m[0m
[0m
[0;31mValueError[0m: operands could not be broadcast together with shapes (3,) (3,2) 
ValueError: operands could not be broadcast together with shapes (3,) (3,2) 

